Workbook

Sheet Read Me
A1: County Watch 2026
A2: What this is
A3: A county-by-county read of the competitive Senate races (AK, GA, IA, KS, ME, MI, MN, MS, NC, NE, NH, OH, SC, TX, FL), plus Virginia and Kentucky as early-closing bellwethers for the national swing.
A4: Before election night it holds the benchmarks (2024 and 2022 results by county, demographics, break-even margins) and the early vote. On the night it projects each race from the counties that have finished counting.
A5: Sheets
A6: Dashboard: one row per state with the projection, swing, confidence and the bot's written read.
A7: Key Counties: 6 to 11 counties per state, on both sides (Democratic vote banks and Republican bases), with why they matter, what to watch, and live status on margin and on turnout. Each state ends with an 'All rural' row: every small-town and rural county together.
A8: County Benchmarks: for each key county, the final margin and net votes that match each statewide outcome (R+5, R+1, tie, D+1, D+5), plus a plain-English line on what to look for. Read final county numbers against these.
A9: First Counties: the first counties to report in each state, in poll-closing order. Shows what arrives first (early, mail or Election Day votes), how lopsided that batch was in 2022, and the first-batch number that only means break-even.
A10: Counties: every county. Grey Feed columns are filled by the bot for GA, NC, MN and NE. Yellow Manual columns are yours: type D and R votes from any source (NYT, AP, a county site) and put Y in 'Manual complete' when a county is fully counted. Manual numbers override the feed.
A11: Types: each kind of county (metro cores, college suburbs, Black Belt, Hispanic, rural...) as a block: its share of the vote, the margin it needs for each statewide outcome, what weaker or stronger turnout does to that, and live swing and turnout. Its swing and turnout pace fill in counties that haven't reported.
A12: Early Vote: statewide early vote for each state, plus North Carolina county by county compared with 2022 at the same point.
... A37: Key county notes are the bot author's judgment; the numbers next to them come from the data above.

Sheet Dashboard
A1: County Watch 2026: competitive Senate races
A2: Projection = counted margin in fully reported counties + every other county's 2024 margin moved by the swing seen in counties of its type. Margins are two-party. Yellow cells are yours to change.
A3: Last bot update: Oct 29 06:09 PM
A5: State | B5: Senate race | C5: Democratic side | D5: Republican | E5: 2024 margin | F5: Swing D needs vs 2024 | G5: Turnout factor (vs 2022) | H5: Expected 2-party votes | I5: Counted 2-party votes | J5: % counted | K5: Counties complete | L5: of | M5: % of expected vote complete | N5: Swing in complete counties | O5: Ahead / behind needed swing | P5: Raw margin | Q5: Projected margin | R5: Leader (projected) | S5: Call | T5: Confidence | U5: Early votes so far | V5: Early vote as % of 2022 turnout | W5: Turnout pace in complete counties (vs 2022) | X5: Turnout pace used for uncounted | Y5: Projected turnout (vs 2022) | Z5: Turnout index: D-leaning complete counties | AA5: Turnout index: R-leaning complete counties | AB5: Latest read (bot)
A6: AK | B6: Alaska Senate | C6: Mary Peltola | D6: Dan Sullivan | E6: =(SUMIFS(Counties!$F$2:$F$1583,Counties!$A$2:$A$1583,$A6)-SUMIFS(Counties!$G$2:$G$1583,Counties!$A$2:$A$1583,$A6))/(SUMIFS(Counties!$F$2:$F$1583,Counties!$A$2:$A$1583,$A6)+SUMIFS(Counties!$G$2:$G$1583,Counties!$A$2:$A$1583,$A6)) | F6: =-SUMIFS(Counties!$AR$2:$AR$1583,Counties!$A$2:$A$1583,$A6)/SUMIFS(Counties!$AQ$2:$AQ$1583,Counties!$A$2:$A$1583,$A6) | G6: 1 | H6: =SUMIFS(Counties!$U$2:$U$1583,Counties!$A$2:$A$1583,$A6) | I6: =SUMIFS(Counties!$AF$2:$AF$1583,Counties!$A$2:$A$1583,$A6) | J6: =IF(H6>0,I6/H6,0) | K6: =COUNTIFS(Counties!$A$2:$A$1583,$A6,Counties!$AG$2:$AG$1583,1) | L6: =COUNTIF(Counties!$A$2:$A$1583,$A6) | M6: =IF(H6>0,SUMIFS(Counties!$U$2:$U$1583,Counties!$A$2:$A$1583,$A6,Counties!$AG$2:$AG$1583,1)/H6,0) | N6: =IF(K6>0,SUMIFS(Counties!$AP$2:$AP$1583,Counties!$A$2:$A$1583,$A6)/SUMIFS(Counties!$AF$2:$AF$1583,Counties!$A$2:$A$1583,$A6,Counties!$AG$2:$AG$1583,1),"") | O6: =IF(N6="","",N6-F6) | P6: =IF(I6>0,(SUMIFS(Counties!$AD$2:$AD$1583,Counties!$A$2:$A$1583,$A6)-SUMIFS(Counties!$AE$2:$AE$1583,Counties!$A$2:$A$1583,$A6))/I6,"") | Q6: =IF(K6>0,(SUMIFS(Counties!$AL$2:$AL$1583,Counties!$A$2:$A$1583,$A6)-SUMIFS(Counties!$AM$2:$AM$1583,Counties!$A$2:$A$1583,$A6))/(SUMIFS(Counties!$AL$2:$AL$1583,Counties!$A$2:$A$1583,$A6)+SUMIFS(Counties!$AM$2:$AM$1583,Counties!$A$2:$A$1583,$A6)),"") | R6: =IF(Q6="","",IF(Q6>=0,C6,D6)&" +"&TEXT(ABS(Q6)*100,"0.0")) | S6: =IF(Q6="","",IF(Q6>=0.05,"Great for "&TRIM(RIGHT(SUBSTITUTE(C6," ",REPT(" ",50)),50)),IF(Q6>=0.01,TRIM(RIGHT(SUBSTITUTE(C6," ",REPT(" ",50)),50))&" on track",IF(Q6>-0.01,"Toss-up",IF(Q6>-0.05,TRIM(RIGHT(SUBSTITUTE(D6," ",REPT(" ",50)),50))&" on track","Great for "&TRIM(RIGHT(SUBSTITUTE(D6," ",REPT(" ",50)),50))))))) | T6: =IF(K6=0,"none",IF(OR(M6<0.1,K6<5),"low",IF(M6<0.4,"medium","high"))) | U6: =IFERROR(INDEX('Early Vote'!$C$6:$C$22,MATCH($A6,'Early Vote'!$A$6:$A$22,0)),"") | V6: =IFERROR(INDEX('Early Vote'!$E$6:$E$22,MATCH($A6,'Early Vote'!$A$6:$A$22,0)),"") | W6: =IF(K6>0,SUMIFS(Counties!$AF$2:$AF$1583,Counties!$A$2:$A$1583,$A6,Counties!$AG$2:$AG$1583,1)/SUMIFS(Counties!$AQ$2:$AQ$1583,Counties!$A$2:$A$1583,$A6,Counties!$AG$2:$AG$1583,1),"") | X6: =IF(K6>=3,W6,G6) | Y6: =SUMIFS(Counties!$AK$2:$AK$1583,Counties!$A$2:$A$1583,$A6)/SUMIFS(Counties!$AQ$2:$AQ$1583,Counties!$A$2:$A$1583,$A6) | Z6: =IFERROR(100*SUMIFS(Counties!$AF$2:$AF$1583,Counties!$A$2:$A$1583,$A6,Counties!$AG$2:$AG$1583,1,Counties!$T$2:$T$1583,">=0.1")/SUMIFS(Counties!$AT$2:$AT$1583,Counties!$A$2:$A$1583,$A6,Counties!$AG$2:$AG$1583,1,Counties!$T$2:$T$1583,">=0.1"),"") | AA6: =IFERROR(100*SUMIFS(Counties!$AF$2:$AF$1583,Counties!$A$2:$A$1583,$A6,Counties!$AG$2:$AG$1583,1,Counties!$T$2:$T$1583,"<=-0.1")/SUMIFS(Counties!$AT$2:$AT$1583,Counties!$A$2:$A$1583,$A6,Counties!$AG$2:$AG$1583,1,Counties!$T$2:$T$1583,"<=-0.1"),"") | AB6: No votes counted yet. 2024: R+13.8; with 2022's turnout pattern R+14.0, so Peltola needs a 14.0-pt swing toward D from 2024 to win.
A7: GA | B7: Georgia Senate | C7: Jon Ossoff | D7: Mike Collins | E7: =(SUMIFS(Counties!$F$2:$F$1583,Counties!$A$2:$A$1583,$A7)-SUMIFS(Counties!$G$2:$G$1583,Counties!$A$2:$A$1583,$A7))/(SUMIFS(Counties!$F$2:$F$1583,Counties!$A$2:$A$1583,$A7)+SUMIFS(Counties!$G$2:$G$1583,Counties!$A$2:$A$1583,$A7)) | F7: =-SUMIFS(Counties!$AR$2:$AR$1583,Counties!$A$2:$A$1583,$A7)/SUMIFS(Counties!$AQ$2:$AQ$1583,Counties!$A$2:$A$1583,$A7) | G7: 1 | H7: =SUMIFS(Counties!$U$2:$U$1583,Counties!$A$2:$A$1583,$A7) | I7: =SUMIFS(Counties!$AF$2:$AF$1583,Counties!$A$2:$A$1583,$A7) | J7: =IF(H7>0,I7/H7,0) | K7: =COUNTIFS(Counties!$A$2:$A$1583,$A7,Counties!$AG$2:$AG$1583,1) | L7: =COUNTIF(Counties!$A$2:$A$1583,$A7) | M7: =IF(H7>0,SUMIFS(Counties!$U$2:$U$1583,Counties!$A$2:$A$1583,$A7,Counties!$AG$2:$AG$1583,1)/H7,0) | N7: =IF(K7>0,SUMIFS(Counties!$AP$2:$AP$1583,Counties!$A$2:$A$1583,$A7)/SUMIFS(Counties!$AF$2:$AF$1583,Counties!$A$2:$A$1583,$A7,Counties!$AG$2:$AG$1583,1),"") | O7: =IF(N7="","",N7-F7) | P7: =IF(I7>0,(SUMIFS(Counties!$AD$2:$AD$1583,Counties!$A$2:$A$1583,$A7)-SUMIFS(Counties!$AE$2:$AE$1583,Counties!$A$2:$A$1583,$A7))/I7,"") | Q7: =IF(K7>0,(SUMIFS(Counties!$AL$2:$AL$1583,Counties!$A$2:$A$1583,$A7)-SUMIFS(Counties!$AM$2:$AM$1583,Counties!$A$2:$A$1583,$A7))/(SUMIFS(Counties!$AL$2:$AL$1583,Counties!$A$2:$A$1583,$A7)+SUMIFS(Counties!$AM$2:$AM$1583,Counties!$A$2:$A$1583,$A7)),"") | R7: =IF(Q7="","",IF(Q7>=0,C7,D7)&" +"&TEXT(ABS(Q7)*100,"0.0")) | S7: =IF(Q7="","",IF(Q7>=0.05,"Great for "&TRIM(RIGHT(SUBSTITUTE(C7," ",REPT(" ",50)),50)),IF(Q7>=0.01,TRIM(RIGHT(SUBSTITUTE(C7," ",REPT(" ",50)),50))&" on track",IF(Q7>-0.01,"Toss-up",IF(Q7>-0.05,TRIM(RIGHT(SUBSTITUTE(D7," ",REPT(" ",50)),50))&" on track","Great for "&TRIM(RIGHT(SUBSTITUTE(D7," ",REPT(" ",50)),50))))))) | T7: =IF(K7=0,"none",IF(OR(M7<0.1,K7<5),"low",IF(M7<0.4,"medium","high"))) | U7: =IFERROR(INDEX('Early Vote'!$C$6:$C$22,MATCH($A7,'Early Vote'!$A$6:$A$22,0)),"") | V7: =IFERROR(INDEX('Early Vote'!$E$6:$E$22,MATCH($A7,'Early Vote'!$A$6:$A$22,0)),"") | W7: =IF(K7>0,SUMIFS(Counties!$AF$2:$AF$1583,Counties!$A$2:$A$1583,$A7,Counties!$AG$2:$AG$1583,1)/SUMIFS(Counties!$AQ$2:$AQ$1583,Counties!$A$2:$A$1583,$A7,Counties!$AG$2:$AG$1583,1),"") | X7: =IF(K7>=3,W7,G7) | Y7: =SUMIFS(Counties!$AK$2:$AK$1583,Counties!$A$2:$A$1583,$A7)/SUMIFS(Counties!$AQ$2:$AQ$1583,Counties!$A$2:$A$1583,$A7) | Z7: =IFERROR(100*SUMIFS(Counties!$AF$2:$AF$1583,Counties!$A$2:$A$1583,$A7,Counties!$AG$2:$AG$1583,1,Counties!$T$2:$T$1583,">=0.1")/SUMIFS(Counties!$AT$2:$AT$1583,Counties!$A$2:$A$1583,$A7,Counties!$AG$2:$AG$1583,1,Counties!$T$2:$T$1583,">=0.1"),"") | AA7: =IFERROR(100*SUMIFS(Counties!$AF$2:$AF$1583,Counties!$A$2:$A$1583,$A7,Counties!$AG$2:$AG$1583,1,Counties!$T$2:$T$1583,"<=-0.1")/SUMIFS(Counties!$AT$2:$AT$1583,Counties!$A$2:$A$1583,$A7,Counties!$AG$2:$AG$1583,1,Counties!$T$2:$T$1583,"<=-0.1"),"") | AB7: No votes counted yet. 2024: R+2.2; with 2022's turnout pattern R+1.1, so Ossoff needs a 1.1-pt swing toward D from 2024 to win. In 2022 the advance vote was D+10.3 and the Election Day vote R+15.9, so counts that are mostly advance votes flatter Democrats.
A8: IA | B8: Iowa Senate | C8: Josh Turek | D8: Ashley Hinson | E8: =(SUMIFS(Counties!$F$2:$F$1583,Counties!$A$2:$A$1583,$A8)-SUMIFS(Counties!$G$2:$G$1583,Counties!$A$2:$A$1583,$A8))/(SUMIFS(Counties!$F$2:$F$1583,Counties!$A$2:$A$1583,$A8)+SUMIFS(Counties!$G$2:$G$1583,Counties!$A$2:$A$1583,$A8)) | F8: =-SUMIFS(Counties!$AR$2:$AR$1583,Counties!$A$2:$A$1583,$A8)/SUMIFS(Counties!$AQ$2:$AQ$1583,Counties!$A$2:$A$1583,$A8) | G8: 1 | H8: =SUMIFS(Counties!$U$2:$U$1583,Counties!$A$2:$A$1583,$A8) | I8: =SUMIFS(Counties!$AF$2:$AF$1583,Counties!$A$2:$A$1583,$A8) | J8: =IF(H8>0,I8/H8,0) | K8: =COUNTIFS(Counties!$A$2:$A$1583,$A8,Counties!$AG$2:$AG$1583,1) | L8: =COUNTIF(Counties!$A$2:$A$1583,$A8) | M8: =IF(H8>0,SUMIFS(Counties!$U$2:$U$1583,Counties!$A$2:$A$1583,$A8,Counties!$AG$2:$AG$1583,1)/H8,0) | N8: =IF(K8>0,SUMIFS(Counties!$AP$2:$AP$1583,Counties!$A$2:$A$1583,$A8)/SUMIFS(Counties!$AF$2:$AF$1583,Counties!$A$2:$A$1583,$A8,Counties!$AG$2:$AG$1583,1),"") | O8: =IF(N8="","",N8-F8) | P8: =IF(I8>0,(SUMIFS(Counties!$AD$2:$AD$1583,Counties!$A$2:$A$1583,$A8)-SUMIFS(Counties!$AE$2:$AE$1583,Counties!$A$2:$A$1583,$A8))/I8,"") | Q8: =IF(K8>0,(SUMIFS(Counties!$AL$2:$AL$1583,Counties!$A$2:$A$1583,$A8)-SUMIFS(Counties!$AM$2:$AM$1583,Counties!$A$2:$A$1583,$A8))/(SUMIFS(Counties!$AL$2:$AL$1583,Counties!$A$2:$A$1583,$A8)+SUMIFS(Counties!$AM$2:$AM$1583,Counties!$A$2:$A$1583,$A8)),"") | R8: =IF(Q8="","",IF(Q8>=0,C8,D8)&" +"&TEXT(ABS(Q8)*100,"0.0")) | S8: =IF(Q8="","",IF(Q8>=0.05,"Great for "&TRIM(RIGHT(SUBSTITUTE(C8," ",REPT(" ",50)),50)),IF(Q8>=0.01,TRIM(RIGHT(SUBSTITUTE(C8," ",REPT(" ",50)),50))&" on track",IF(Q8>-0.01,"Toss-up",IF(Q8>-0.05,TRIM(RIGHT(SUBSTITUTE(D8," ",REPT(" ",50)),50))&" on track","Great for "&TRIM(RIGHT(SUBSTITUTE(D8," ",REPT(" ",50)),50))))))) | T8: =IF(K8=0,"none",IF(OR(M8<0.1,K8<5),"low",IF(M8<0.4,"medium","high"))) | U8: =IFERROR(INDEX('Early Vote'!$C$6:$C$22,MATCH($A8,'Early Vote'!$A$6:$A$22,0)),"") | V8: =IFERROR(INDEX('Early Vote'!$E$6:$E$22,MATCH($A8,'Early Vote'!$A$6:$A$22,0)),"") | W8: =IF(K8>0,SUMIFS(Counties!$AF$2:$AF$1583,Counties!$A$2:$A$1583,$A8,Counties!$AG$2:$AG$1583,1)/SUMIFS(Counties!$AQ$2:$AQ$1583,Counties!$A$2:$A$1583,$A8,Counties!$AG$2:$AG$1583,1),"") | X8: =IF(K8>=3,W8,G8) | Y8: =SUMIFS(Counties!$AK$2:$AK$1583,Counties!$A$2:$A$1583,$A8)/SUMIFS(Counties!$AQ$2:$AQ$1583,Counties!$A$2:$A$1583,$A8) | Z8: =IFERROR(100*SUMIFS(Counties!$AF$2:$AF$1583,Counties!$A$2:$A$1583,$A8,Counties!$AG$2:$AG$1583,1,Counties!$T$2:$T$1583,">=0.1")/SUMIFS(Counties!$AT$2:$AT$1583,Counties!$A$2:$A$1583,$A8,Counties!$AG$2:$AG$1583,1,Counties!$T$2:$T$1583,">=0.1"),"") | AA8: =IFERROR(100*SUMIFS(Counties!$AF$2:$AF$1583,Counties!$A$2:$A$1583,$A8,Counties!$AG$2:$AG$1583,1,Counties!$T$2:$T$1583,"<=-0.1")/SUMIFS(Counties!$AT$2:$AT$1583,Counties!$A$2:$A$1583,$A8,Counties!$AG$2:$AG$1583,1,Counties!$T$2:$T$1583,"<=-0.1"),"") | AB8: No votes counted yet. 2024: R+13.4; with 2022's turnout pattern R+13.2, so Turek needs a 13.2-pt swing toward D from 2024 to win. In 2022 the early/absentee vote was D+19.7 and the Election Day vote R+25.9, so counts that are mostly early/absentee votes flatter Democrats.
A9: KS | B9: Kansas Senate | C9: Adam Hamilton | D9: Roger Marshall | E9: =(SUMIFS(Counties!$F$2:$F$1583,Counties!$A$2:$A$1583,$A9)-SUMIFS(Counties!$G$2:$G$1583,Counties!$A$2:$A$1583,$A9))/(SUMIFS(Counties!$F$2:$F$1583,Counties!$A$2:$A$1583,$A9)+SUMIFS(Counties!$G$2:$G$1583,Counties!$A$2:$A$1583,$A9)) | F9: =-SUMIFS(Counties!$AR$2:$AR$1583,Counties!$A$2:$A$1583,$A9)/SUMIFS(Counties!$AQ$2:$AQ$1583,Counties!$A$2:$A$1583,$A9) | G9: 1 | H9: =SUMIFS(Counties!$U$2:$U$1583,Counties!$A$2:$A$1583,$A9) | I9: =SUMIFS(Counties!$AF$2:$AF$1583,Counties!$A$2:$A$1583,$A9) | J9: =IF(H9>0,I9/H9,0) | K9: =COUNTIFS(Counties!$A$2:$A$1583,$A9,Counties!$AG$2:$AG$1583,1) | L9: =COUNTIF(Counties!$A$2:$A$1583,$A9) | M9: =IF(H9>0,SUMIFS(Counties!$U$2:$U$1583,Counties!$A$2:$A$1583,$A9,Counties!$AG$2:$AG$1583,1)/H9,0) | N9: =IF(K9>0,SUMIFS(Counties!$AP$2:$AP$1583,Counties!$A$2:$A$1583,$A9)/SUMIFS(Counties!$AF$2:$AF$1583,Counties!$A$2:$A$1583,$A9,Counties!$AG$2:$AG$1583,1),"") | O9: =IF(N9="","",N9-F9) | P9: =IF(I9>0,(SUMIFS(Counties!$AD$2:$AD$1583,Counties!$A$2:$A$1583,$A9)-SUMIFS(Counties!$AE$2:$AE$1583,Counties!$A$2:$A$1583,$A9))/I9,"") | Q9: =IF(K9>0,(SUMIFS(Counties!$AL$2:$AL$1583,Counties!$A$2:$A$1583,$A9)-SUMIFS(Counties!$AM$2:$AM$1583,Counties!$A$2:$A$1583,$A9))/(SUMIFS(Counties!$AL$2:$AL$1583,Counties!$A$2:$A$1583,$A9)+SUMIFS(Counties!$AM$2:$AM$1583,Counties!$A$2:$A$1583,$A9)),"") | R9: =IF(Q9="","",IF(Q9>=0,C9,D9)&" +"&TEXT(ABS(Q9)*100,"0.0")) | S9: =IF(Q9="","",IF(Q9>=0.05,"Great for "&TRIM(RIGHT(SUBSTITUTE(C9," ",REPT(" ",50)),50)),IF(Q9>=0.01,TRIM(RIGHT(SUBSTITUTE(C9," ",REPT(" ",50)),50))&" on track",IF(Q9>-0.01,"Toss-up",IF(Q9>-0.05,TRIM(RIGHT(SUBSTITUTE(D9," ",REPT(" ",50)),50))&" on track","Great for "&TRIM(RIGHT(SUBSTITUTE(D9," ",REPT(" ",50)),50))))))) | T9: =IF(K9=0,"none",IF(OR(M9<0.1,K9<5),"low",IF(M9<0.4,"medium","high"))) | U9: =IFERROR(INDEX('Early Vote'!$C$6:$C$22,MATCH($A9,'Early Vote'!$A$6:$A$22,0)),"") | V9: =IFERROR(INDEX('Early Vote'!$E$6:$E$22,MATCH($A9,'Early Vote'!$A$6:$A$22,0)),"") | W9: =IF(K9>0,SUMIFS(Counties!$AF$2:$AF$1583,Counties!$A$2:$A$1583,$A9,Counties!$AG$2:$AG$1583,1)/SUMIFS(Counties!$AQ$2:$AQ$1583,Counties!$A$2:$A$1583,$A9,Counties!$AG$2:$AG$1583,1),"") | X9: =IF(K9>=3,W9,G9) | Y9: =SUMIFS(Counties!$AK$2:$AK$1583,Counties!$A$2:$A$1583,$A9)/SUMIFS(Counties!$AQ$2:$AQ$1583,Counties!$A$2:$A$1583,$A9) | Z9: =IFERROR(100*SUMIFS(Counties!$AF$2:$AF$1583,Counties!$A$2:$A$1583,$A9,Counties!$AG$2:$AG$1583,1,Counties!$T$2:$T$1583,">=0.1")/SUMIFS(Counties!$AT$2:$AT$1583,Counties!$A$2:$A$1583,$A9,Counties!$AG$2:$AG$1583,1,Counties!$T$2:$T$1583,">=0.1"),"") | AA9: =IFERROR(100*SUMIFS(Counties!$AF$2:$AF$1583,Counties!$A$2:$A$1583,$A9,Counties!$AG$2:$AG$1583,1,Counties!$T$2:$T$1583,"<=-0.1")/SUMIFS(Counties!$AT$2:$AT$1583,Counties!$A$2:$A$1583,$A9,Counties!$AG$2:$AG$1583,1,Counties!$T$2:$T$1583,"<=-0.1"),"") | AB9: No votes counted yet. 2024: R+16.4; with 2022's turnout pattern R+16.5, so Hamilton needs a 16.5-pt swing toward D from 2024 to win.
A10: ME | B10: Maine Senate | C10: Troy Jackson | D10: Susan Collins | E10: =(SUMIFS(Counties!$F$2:$F$1583,Counties!$A$2:$A$1583,$A10)-SUMIFS(Counties!$G$2:$G$1583,Counties!$A$2:$A$1583,$A10))/(SUMIFS(Counties!$F$2:$F$1583,Counties!$A$2:$A$1583,$A10)+SUMIFS(Counties!$G$2:$G$1583,Counties!$A$2:$A$1583,$A10)) | F10: =-SUMIFS(Counties!$AR$2:$AR$1583,Counties!$A$2:$A$1583,$A10)/SUMIFS(Counties!$AQ$2:$AQ$1583,Counties!$A$2:$A$1583,$A10) | G10: 1 | H10: =SUMIFS(Counties!$U$2:$U$1583,Counties!$A$2:$A$1583,$A10) | I10: =SUMIFS(Counties!$AF$2:$AF$1583,Counties!$A$2:$A$1583,$A10) | J10: =IF(H10>0,I10/H10,0) | K10: =COUNTIFS(Counties!$A$2:$A$1583,$A10,Counties!$AG$2:$AG$1583,1) | L10: =COUNTIF(Counties!$A$2:$A$1583,$A10) | M10: =IF(H10>0,SUMIFS(Counties!$U$2:$U$1583,Counties!$A$2:$A$1583,$A10,Counties!$AG$2:$AG$1583,1)/H10,0) | N10: =IF(K10>0,SUMIFS(Counties!$AP$2:$AP$1583,Counties!$A$2:$A$1583,$A10)/SUMIFS(Counties!$AF$2:$AF$1583,Counties!$A$2:$A$1583,$A10,Counties!$AG$2:$AG$1583,1),"") | O10: =IF(N10="","",N10-F10) | P10: =IF(I10>0,(SUMIFS(Counties!$AD$2:$AD$1583,Counties!$A$2:$A$1583,$A10)-SUMIFS(Counties!$AE$2:$AE$1583,Counties!$A$2:$A$1583,$A10))/I10,"") | Q10: =IF(K10>0,(SUMIFS(Counties!$AL$2:$AL$1583,Counties!$A$2:$A$1583,$A10)-SUMIFS(Counties!$AM$2:$AM$1583,Counties!$A$2:$A$1583,$A10))/(SUMIFS(Counties!$AL$2:$AL$1583,Counties!$A$2:$A$1583,$A10)+SUMIFS(Counties!$AM$2:$AM$1583,Counties!$A$2:$A$1583,$A10)),"") | R10: =IF(Q10="","",IF(Q10>=0,C10,D10)&" +"&TEXT(ABS(Q10)*100,"0.0")) | S10: =IF(Q10="","",IF(Q10>=0.05,"Great for "&TRIM(RIGHT(SUBSTITUTE(C10," ",REPT(" ",50)),50)),IF(Q10>=0.01,TRIM(RIGHT(SUBSTITUTE(C10," ",REPT(" ",50)),50))&" on track",IF(Q10>-0.01,"Toss-up",IF(Q10>-0.05,TRIM(RIGHT(SUBSTITUTE(D10," ",REPT(" ",50)),50))&" on track","Great for "&TRIM(RIGHT(SUBSTITUTE(D10," ",REPT(" ",50)),50))))))) | T10: =IF(K10=0,"none",IF(OR(M10<0.1,K10<5),"low",IF(M10<0.4,"medium","high"))) | U10: =IFERROR(INDEX('Early Vote'!$C$6:$C$22,MATCH($A10,'Early Vote'!$A$6:$A$22,0)),"") | V10: =IFERROR(INDEX('Early Vote'!$E$6:$E$22,MATCH($A10,'Early Vote'!$A$6:$A$22,0)),"") | W10: =IF(K10>0,SUMIFS(Counties!$AF$2:$AF$1583,Counties!$A$2:$A$1583,$A10,Counties!$AG$2:$AG$1583,1)/SUMIFS(Counties!$AQ$2:$AQ$1583,Counties!$A$2:$A$1583,$A10,Counties!$AG$2:$AG$1583,1),"") | X10: =IF(K10>=3,W10,G10) | Y10: =SUMIFS(Counties!$AK$2:$AK$1583,Counties!$A$2:$A$1583,$A10)/SUMIFS(Counties!$AQ$2:$AQ$1583,Counties!$A$2:$A$1583,$A10) | Z10: =IFERROR(100*SUMIFS(Counties!$AF$2:$AF$1583,Counties!$A$2:$A$1583,$A10,Counties!$AG$2:$AG$1583,1,Counties!$T$2:$T$1583,">=0.1")/SUMIFS(Counties!$AT$2:$AT$1583,Counties!$A$2:$A$1583,$A10,Counties!$AG$2:$AG$1583,1,Counties!$T$2:$T$1583,">=0.1"),"") | AA10: =IFERROR(100*SUMIFS(Counties!$AF$2:$AF$1583,Counties!$A$2:$A$1583,$A10,Counties!$AG$2:$AG$1583,1,Counties!$T$2:$T$1583,"<=-0.1")/SUMIFS(Counties!$AT$2:$AT$1583,Counties!$A$2:$A$1583,$A10,Counties!$AG$2:$AG$1583,1,Counties!$T$2:$T$1583,"<=-0.1"),"") | AB10: No votes counted yet. 2024: D+7.1; with 2022's turnout pattern D+7.2, so Jackson can absorb up to a 7.2-pt swing toward R from 2024 and still win.
A11: MI | B11: Michigan Senate | C11: Abdul El-Sayed | D11: Mike Rogers | E11: =(SUMIFS(Counties!$F$2:$F$1583,Counties!$A$2:$A$1583,$A11)-SUMIFS(Counties!$G$2:$G$1583,Counties!$A$2:$A$1583,$A11))/(SUMIFS(Counties!$F$2:$F$1583,Counties!$A$2:$A$1583,$A11)+SUMIFS(Counties!$G$2:$G$1583,Counties!$A$2:$A$1583,$A11)) | F11: =-SUMIFS(Counties!$AR$2:$AR$1583,Counties!$A$2:$A$1583,$A11)/SUMIFS(Counties!$AQ$2:$AQ$1583,Counties!$A$2:$A$1583,$A11) | G11: 1 | H11: =SUMIFS(Counties!$U$2:$U$1583,Counties!$A$2:$A$1583,$A11) | I11: =SUMIFS(Counties!$AF$2:$AF$1583,Counties!$A$2:$A$1583,$A11) | J11: =IF(H11>0,I11/H11,0) | K11: =COUNTIFS(Counties!$A$2:$A$1583,$A11,Counties!$AG$2:$AG$1583,1) | L11: =COUNTIF(Counties!$A$2:$A$1583,$A11) | M11: =IF(H11>0,SUMIFS(Counties!$U$2:$U$1583,Counties!$A$2:$A$1583,$A11,Counties!$AG$2:$AG$1583,1)/H11,0) | N11: =IF(K11>0,SUMIFS(Counties!$AP$2:$AP$1583,Counties!$A$2:$A$1583,$A11)/SUMIFS(Counties!$AF$2:$AF$1583,Counties!$A$2:$A$1583,$A11,Counties!$AG$2:$AG$1583,1),"") | O11: =IF(N11="","",N11-F11) | P11: =IF(I11>0,(SUMIFS(Counties!$AD$2:$AD$1583,Counties!$A$2:$A$1583,$A11)-SUMIFS(Counties!$AE$2:$AE$1583,Counties!$A$2:$A$1583,$A11))/I11,"") | Q11: =IF(K11>0,(SUMIFS(Counties!$AL$2:$AL$1583,Counties!$A$2:$A$1583,$A11)-SUMIFS(Counties!$AM$2:$AM$1583,Counties!$A$2:$A$1583,$A11))/(SUMIFS(Counties!$AL$2:$AL$1583,Counties!$A$2:$A$1583,$A11)+SUMIFS(Counties!$AM$2:$AM$1583,Counties!$A$2:$A$1583,$A11)),"") | R11: =IF(Q11="","",IF(Q11>=0,C11,D11)&" +"&TEXT(ABS(Q11)*100,"0.0")) | S11: =IF(Q11="","",IF(Q11>=0.05,"Great for "&TRIM(RIGHT(SUBSTITUTE(C11," ",REPT(" ",50)),50)),IF(Q11>=0.01,TRIM(RIGHT(SUBSTITUTE(C11," ",REPT(" ",50)),50))&" on track",IF(Q11>-0.01,"Toss-up",IF(Q11>-0.05,TRIM(RIGHT(SUBSTITUTE(D11," ",REPT(" ",50)),50))&" on track","Great for "&TRIM(RIGHT(SUBSTITUTE(D11," ",REPT(" ",50)),50))))))) | T11: =IF(K11=0,"none",IF(OR(M11<0.1,K11<5),"low",IF(M11<0.4,"medium","high"))) | U11: =IFERROR(INDEX('Early Vote'!$C$6:$C$22,MATCH($A11,'Early Vote'!$A$6:$A$22,0)),"") | V11: =IFERROR(INDEX('Early Vote'!$E$6:$E$22,MATCH($A11,'Early Vote'!$A$6:$A$22,0)),"") | W11: =IF(K11>0,SUMIFS(Counties!$AF$2:$AF$1583,Counties!$A$2:$A$1583,$A11,Counties!$AG$2:$AG$1583,1)/SUMIFS(Counties!$AQ$2:$AQ$1583,Counties!$A$2:$A$1583,$A11,Counties!$AG$2:$AG$1583,1),"") | X11: =IF(K11>=3,W11,G11) | Y11: =SUMIFS(Counties!$AK$2:$AK$1583,Counties!$A$2:$A$1583,$A11)/SUMIFS(Counties!$AQ$2:$AQ$1583,Counties!$A$2:$A$1583,$A11) | Z11: =IFERROR(100*SUMIFS(Counties!$AF$2:$AF$1583,Counties!$A$2:$A$1583,$A11,Counties!$AG$2:$AG$1583,1,Counties!$T$2:$T$1583,">=0.1")/SUMIFS(Counties!$AT$2:$AT$1583,Counties!$A$2:$A$1583,$A11,Counties!$AG$2:$AG$1583,1,Counties!$T$2:$T$1583,">=0.1"),"") | AA11: =IFERROR(100*SUMIFS(Counties!$AF$2:$AF$1583,Counties!$A$2:$A$1583,$A11,Counties!$AG$2:$AG$1583,1,Counties!$T$2:$T$1583,"<=-0.1")/SUMIFS(Counties!$AT$2:$AT$1583,Counties!$A$2:$A$1583,$A11,Counties!$AG$2:$AG$1583,1,Counties!$T$2:$T$1583,"<=-0.1"),"") | AB11: No votes counted yet. 2024: R+1.4; with 2022's turnout pattern R+1.8, so El-Sayed needs a 1.8-pt swing toward D from 2024 to win.
A12: MN | B12: Minnesota Senate | C12: Peggy Flanagan | D12: Michele Tafoya | E12: =(SUMIFS(Counties!$F$2:$F$1583,Counties!$A$2:$A$1583,$A12)-SUMIFS(Counties!$G$2:$G$1583,Counties!$A$2:$A$1583,$A12))/(SUMIFS(Counties!$F$2:$F$1583,Counties!$A$2:$A$1583,$A12)+SUMIFS(Counties!$G$2:$G$1583,Counties!$A$2:$A$1583,$A12)) | F12: =-SUMIFS(Counties!$AR$2:$AR$1583,Counties!$A$2:$A$1583,$A12)/SUMIFS(Counties!$AQ$2:$AQ$1583,Counties!$A$2:$A$1583,$A12) | G12: 1 | H12: =SUMIFS(Counties!$U$2:$U$1583,Counties!$A$2:$A$1583,$A12) | I12: =SUMIFS(Counties!$AF$2:$AF$1583,Counties!$A$2:$A$1583,$A12) | J12: =IF(H12>0,I12/H12,0) | K12: =COUNTIFS(Counties!$A$2:$A$1583,$A12,Counties!$AG$2:$AG$1583,1) | L12: =COUNTIF(Counties!$A$2:$A$1583,$A12) | M12: =IF(H12>0,SUMIFS(Counties!$U$2:$U$1583,Counties!$A$2:$A$1583,$A12,Counties!$AG$2:$AG$1583,1)/H12,0) | N12: =IF(K12>0,SUMIFS(Counties!$AP$2:$AP$1583,Counties!$A$2:$A$1583,$A12)/SUMIFS(Counties!$AF$2:$AF$1583,Counties!$A$2:$A$1583,$A12,Counties!$AG$2:$AG$1583,1),"") | O12: =IF(N12="","",N12-F12) | P12: =IF(I12>0,(SUMIFS(Counties!$AD$2:$AD$1583,Counties!$A$2:$A$1583,$A12)-SUMIFS(Counties!$AE$2:$AE$1583,Counties!$A$2:$A$1583,$A12))/I12,"") | Q12: =IF(K12>0,(SUMIFS(Counties!$AL$2:$AL$1583,Counties!$A$2:$A$1583,$A12)-SUMIFS(Counties!$AM$2:$AM$1583,Counties!$A$2:$A$1583,$A12))/(SUMIFS(Counties!$AL$2:$AL$1583,Counties!$A$2:$A$1583,$A12)+SUMIFS(Counties!$AM$2:$AM$1583,Counties!$A$2:$A$1583,$A12)),"") | R12: =IF(Q12="","",IF(Q12>=0,C12,D12)&" +"&TEXT(ABS(Q12)*100,"0.0")) | S12: =IF(Q12="","",IF(Q12>=0.05,"Great for "&TRIM(RIGHT(SUBSTITUTE(C12," ",REPT(" ",50)),50)),IF(Q12>=0.01,TRIM(RIGHT(SUBSTITUTE(C12," ",REPT(" ",50)),50))&" on track",IF(Q12>-0.01,"Toss-up",IF(Q12>-0.05,TRIM(RIGHT(SUBSTITUTE(D12," ",REPT(" ",50)),50))&" on track","Great for "&TRIM(RIGHT(SUBSTITUTE(D12," ",REPT(" ",50)),50))))))) | T12: =IF(K12=0,"none",IF(OR(M12<0.1,K12<5),"low",IF(M12<0.4,"medium","high"))) | U12: =IFERROR(INDEX('Early Vote'!$C$6:$C$22,MATCH($A12,'Early Vote'!$A$6:$A$22,0)),"") | V12: =IFERROR(INDEX('Early Vote'!$E$6:$E$22,MATCH($A12,'Early Vote'!$A$6:$A$22,0)),"") | W12: =IF(K12>0,SUMIFS(Counties!$AF$2:$AF$1583,Counties!$A$2:$A$1583,$A12,Counties!$AG$2:$AG$1583,1)/SUMIFS(Counties!$AQ$2:$AQ$1583,Counties!$A$2:$A$1583,$A12,Counties!$AG$2:$AG$1583,1),"") | X12: =IF(K12>=3,W12,G12) | Y12: =SUMIFS(Counties!$AK$2:$AK$1583,Counties!$A$2:$A$1583,$A12)/SUMIFS(Counties!$AQ$2:$AQ$1583,Counties!$A$2:$A$1583,$A12) | Z12: =IFERROR(100*SUMIFS(Counties!$AF$2:$AF$1583,Counties!$A$2:$A$1583,$A12,Counties!$AG$2:$AG$1583,1,Counties!$T$2:$T$1583,">=0.1")/SUMIFS(Counties!$AT$2:$AT$1583,Counties!$A$2:$A$1583,$A12,Counties!$AG$2:$AG$1583,1,Counties!$T$2:$T$1583,">=0.1"),"") | AA12: =IFERROR(100*SUMIFS(Counties!$AF$2:$AF$1583,Counties!$A$2:$A$1583,$A12,Counties!$AG$2:$AG$1583,1,Counties!$T$2:$T$1583,"<=-0.1")/SUMIFS(Counties!$AT$2:$AT$1583,Counties!$A$2:$A$1583,$A12,Counties!$AG$2:$AG$1583,1,Counties!$T$2:$T$1583,"<=-0.1"),"") | AB12: No votes counted yet. 2024: D+4.3; with 2022's turnout pattern D+4.9, so Flanagan can absorb up to a 4.9-pt swing toward R from 2024 and still win.
A13: MS | B13: Mississippi Senate | C13: Scott Colom | D13: Cindy Hyde-Smith | E13: =(SUMIFS(Counties!$F$2:$F$1583,Counties!$A$2:$A$1583,$A13)-SUMIFS(Counties!$G$2:$G$1583,Counties!$A$2:$A$1583,$A13))/(SUMIFS(Counties!$F$2:$F$1583,Counties!$A$2:$A$1583,$A13)+SUMIFS(Counties!$G$2:$G$1583,Counties!$A$2:$A$1583,$A13)) | F13: =-SUMIFS(Counties!$AR$2:$AR$1583,Counties!$A$2:$A$1583,$A13)/SUMIFS(Counties!$AQ$2:$AQ$1583,Counties!$A$2:$A$1583,$A13) | G13: 1 | H13: =SUMIFS(Counties!$U$2:$U$1583,Counties!$A$2:$A$1583,$A13) | I13: =SUMIFS(Counties!$AF$2:$AF$1583,Counties!$A$2:$A$1583,$A13) | J13: =IF(H13>0,I13/H13,0) | K13: =COUNTIFS(Counties!$A$2:$A$1583,$A13,Counties!$AG$2:$AG$1583,1) | L13: =COUNTIF(Counties!$A$2:$A$1583,$A13) | M13: =IF(H13>0,SUMIFS(Counties!$U$2:$U$1583,Counties!$A$2:$A$1583,$A13,Counties!$AG$2:$AG$1583,1)/H13,0) | N13: =IF(K13>0,SUMIFS(Counties!$AP$2:$AP$1583,Counties!$A$2:$A$1583,$A13)/SUMIFS(Counties!$AF$2:$AF$1583,Counties!$A$2:$A$1583,$A13,Counties!$AG$2:$AG$1583,1),"") | O13: =IF(N13="","",N13-F13) | P13: =IF(I13>0,(SUMIFS(Counties!$AD$2:$AD$1583,Counties!$A$2:$A$1583,$A13)-SUMIFS(Counties!$AE$2:$AE$1583,Counties!$A$2:$A$1583,$A13))/I13,"") | Q13: =IF(K13>0,(SUMIFS(Counties!$AL$2:$AL$1583,Counties!$A$2:$A$1583,$A13)-SUMIFS(Counties!$AM$2:$AM$1583,Counties!$A$2:$A$1583,$A13))/(SUMIFS(Counties!$AL$2:$AL$1583,Counties!$A$2:$A$1583,$A13)+SUMIFS(Counties!$AM$2:$AM$1583,Counties!$A$2:$A$1583,$A13)),"") | R13: =IF(Q13="","",IF(Q13>=0,C13,D13)&" +"&TEXT(ABS(Q13)*100,"0.0")) | S13: =IF(Q13="","",IF(Q13>=0.05,"Great for "&TRIM(RIGHT(SUBSTITUTE(C13," ",REPT(" ",50)),50)),IF(Q13>=0.01,TRIM(RIGHT(SUBSTITUTE(C13," ",REPT(" ",50)),50))&" on track",IF(Q13>-0.01,"Toss-up",IF(Q13>-0.05,TRIM(RIGHT(SUBSTITUTE(D13," ",REPT(" ",50)),50))&" on track","Great for "&TRIM(RIGHT(SUBSTITUTE(D13," ",REPT(" ",50)),50))))))) | T13: =IF(K13=0,"none",IF(OR(M13<0.1,K13<5),"low",IF(M13<0.4,"medium","high"))) | U13: =IFERROR(INDEX('Early Vote'!$C$6:$C$22,MATCH($A13,'Early Vote'!$A$6:$A$22,0)),"") | V13: =IFERROR(INDEX('Early Vote'!$E$6:$E$22,MATCH($A13,'Early Vote'!$A$6:$A$22,0)),"") | W13: =IF(K13>0,SUMIFS(Counties!$AF$2:$AF$1583,Counties!$A$2:$A$1583,$A13,Counties!$AG$2:$AG$1583,1)/SUMIFS(Counties!$AQ$2:$AQ$1583,Counties!$A$2:$A$1583,$A13,Counties!$AG$2:$AG$1583,1),"") | X13: =IF(K13>=3,W13,G13) | Y13: =SUMIFS(Counties!$AK$2:$AK$1583,Counties!$A$2:$A$1583,$A13)/SUMIFS(Counties!$AQ$2:$AQ$1583,Counties!$A$2:$A$1583,$A13) | Z13: =IFERROR(100*SUMIFS(Counties!$AF$2:$AF$1583,Counties!$A$2:$A$1583,$A13,Counties!$AG$2:$AG$1583,1,Counties!$T$2:$T$1583,">=0.1")/SUMIFS(Counties!$AT$2:$AT$1583,Counties!$A$2:$A$1583,$A13,Counties!$AG$2:$AG$1583,1,Counties!$T$2:$T$1583,">=0.1"),"") | AA13: =IFERROR(100*SUMIFS(Counties!$AF$2:$AF$1583,Counties!$A$2:$A$1583,$A13,Counties!$AG$2:$AG$1583,1,Counties!$T$2:$T$1583,"<=-0.1")/SUMIFS(Counties!$AT$2:$AT$1583,Counties!$A$2:$A$1583,$A13,Counties!$AG$2:$AG$1583,1,Counties!$T$2:$T$1583,"<=-0.1"),"") | AB13: No votes counted yet. 2024: R+23.1; with 2022's turnout pattern R+21.8, so Colom needs a 21.8-pt swing toward D from 2024 to win.
A14: NC | B14: North Carolina Senate | C14: Roy Cooper | D14: Michael Whatley | E14: =(SUMIFS(Counties!$F$2:$F$1583,Counties!$A$2:$A$1583,$A14)-SUMIFS(Counties!$G$2:$G$1583,Counties!$A$2:$A$1583,$A14))/(SUMIFS(Counties!$F$2:$F$1583,Counties!$A$2:$A$1583,$A14)+SUMIFS(Counties!$G$2:$G$1583,Counties!$A$2:$A$1583,$A14)) | F14: =-SUMIFS(Counties!$AR$2:$AR$1583,Counties!$A$2:$A$1583,$A14)/SUMIFS(Counties!$AQ$2:$AQ$1583,Counties!$A$2:$A$1583,$A14) | G14: 1 | H14: =SUMIFS(Counties!$U$2:$U$1583,Counties!$A$2:$A$1583,$A14) | I14: =SUMIFS(Counties!$AF$2:$AF$1583,Counties!$A$2:$A$1583,$A14) | J14: =IF(H14>0,I14/H14,0) | K14: =COUNTIFS(Counties!$A$2:$A$1583,$A14,Counties!$AG$2:$AG$1583,1) | L14: =COUNTIF(Counties!$A$2:$A$1583,$A14) | M14: =IF(H14>0,SUMIFS(Counties!$U$2:$U$1583,Counties!$A$2:$A$1583,$A14,Counties!$AG$2:$AG$1583,1)/H14,0) | N14: =IF(K14>0,SUMIFS(Counties!$AP$2:$AP$1583,Counties!$A$2:$A$1583,$A14)/SUMIFS(Counties!$AF$2:$AF$1583,Counties!$A$2:$A$1583,$A14,Counties!$AG$2:$AG$1583,1),"") | O14: =IF(N14="","",N14-F14) | P14: =IF(I14>0,(SUMIFS(Counties!$AD$2:$AD$1583,Counties!$A$2:$A$1583,$A14)-SUMIFS(Counties!$AE$2:$AE$1583,Counties!$A$2:$A$1583,$A14))/I14,"") | Q14: =IF(K14>0,(SUMIFS(Counties!$AL$2:$AL$1583,Counties!$A$2:$A$1583,$A14)-SUMIFS(Counties!$AM$2:$AM$1583,Counties!$A$2:$A$1583,$A14))/(SUMIFS(Counties!$AL$2:$AL$1583,Counties!$A$2:$A$1583,$A14)+SUMIFS(Counties!$AM$2:$AM$1583,Counties!$A$2:$A$1583,$A14)),"") | R14: =IF(Q14="","",IF(Q14>=0,C14,D14)&" +"&TEXT(ABS(Q14)*100,"0.0")) | S14: =IF(Q14="","",IF(Q14>=0.05,"Great for "&TRIM(RIGHT(SUBSTITUTE(C14," ",REPT(" ",50)),50)),IF(Q14>=0.01,TRIM(RIGHT(SUBSTITUTE(C14," ",REPT(" ",50)),50))&" on track",IF(Q14>-0.01,"Toss-up",IF(Q14>-0.05,TRIM(RIGHT(SUBSTITUTE(D14," ",REPT(" ",50)),50))&" on track","Great for "&TRIM(RIGHT(SUBSTITUTE(D14," ",REPT(" ",50)),50))))))) | T14: =IF(K14=0,"none",IF(OR(M14<0.1,K14<5),"low",IF(M14<0.4,"medium","high"))) | U14: =IFERROR(INDEX('Early Vote'!$C$6:$C$22,MATCH($A14,'Early Vote'!$A$6:$A$22,0)),"") | V14: =IFERROR(INDEX('Early Vote'!$E$6:$E$22,MATCH($A14,'Early Vote'!$A$6:$A$22,0)),"") | W14: =IF(K14>0,SUMIFS(Counties!$AF$2:$AF$1583,Counties!$A$2:$A$1583,$A14,Counties!$AG$2:$AG$1583,1)/SUMIFS(Counties!$AQ$2:$AQ$1583,Counties!$A$2:$A$1583,$A14,Counties!$AG$2:$AG$1583,1),"") | X14: =IF(K14>=3,W14,G14) | Y14: =SUMIFS(Counties!$AK$2:$AK$1583,Counties!$A$2:$A$1583,$A14)/SUMIFS(Counties!$AQ$2:$AQ$1583,Counties!$A$2:$A$1583,$A14) | Z14: =IFERROR(100*SUMIFS(Counties!$AF$2:$AF$1583,Counties!$A$2:$A$1583,$A14,Counties!$AG$2:$AG$1583,1,Counties!$T$2:$T$1583,">=0.1")/SUMIFS(Counties!$AT$2:$AT$1583,Counties!$A$2:$A$1583,$A14,Counties!$AG$2:$AG$1583,1,Counties!$T$2:$T$1583,">=0.1"),"") | AA14: =IFERROR(100*SUMIFS(Counties!$AF$2:$AF$1583,Counties!$A$2:$A$1583,$A14,Counties!$AG$2:$AG$1583,1,Counties!$T$2:$T$1583,"<=-0.1")/SUMIFS(Counties!$AT$2:$AT$1583,Counties!$A$2:$A$1583,$A14,Counties!$AG$2:$AG$1583,1,Counties!$T$2:$T$1583,"<=-0.1"),"") | AB14: No votes counted yet. 2024: R+3.3; with 2022's turnout pattern R+2.8, so Cooper needs a 2.8-pt swing toward D from 2024 to win. In 2022 the early vote was D+9.0 and the Election Day vote R+20.7, so counts that are mostly early votes flatter Democrats.
A15: NE | B15: Nebraska Senate | C15: Dan Osborn | D15: Pete Ricketts | E15: =(SUMIFS(Counties!$F$2:$F$1583,Counties!$A$2:$A$1583,$A15)-SUMIFS(Counties!$G$2:$G$1583,Counties!$A$2:$A$1583,$A15))/(SUMIFS(Counties!$F$2:$F$1583,Counties!$A$2:$A$1583,$A15)+SUMIFS(Counties!$G$2:$G$1583,Counties!$A$2:$A$1583,$A15)) | F15: =-SUMIFS(Counties!$AR$2:$AR$1583,Counties!$A$2:$A$1583,$A15)/SUMIFS(Counties!$AQ$2:$AQ$1583,Counties!$A$2:$A$1583,$A15) | G15: 1 | H15: =SUMIFS(Counties!$U$2:$U$1583,Counties!$A$2:$A$1583,$A15) | I15: =SUMIFS(Counties!$AF$2:$AF$1583,Counties!$A$2:$A$1583,$A15) | J15: =IF(H15>0,I15/H15,0) | K15: =COUNTIFS(Counties!$A$2:$A$1583,$A15,Counties!$AG$2:$AG$1583,1) | L15: =COUNTIF(Counties!$A$2:$A$1583,$A15) | M15: =IF(H15>0,SUMIFS(Counties!$U$2:$U$1583,Counties!$A$2:$A$1583,$A15,Counties!$AG$2:$AG$1583,1)/H15,0) | N15: =IF(K15>0,SUMIFS(Counties!$AP$2:$AP$1583,Counties!$A$2:$A$1583,$A15)/SUMIFS(Counties!$AF$2:$AF$1583,Counties!$A$2:$A$1583,$A15,Counties!$AG$2:$AG$1583,1),"") | O15: =IF(N15="","",N15-F15) | P15: =IF(I15>0,(SUMIFS(Counties!$AD$2:$AD$1583,Counties!$A$2:$A$1583,$A15)-SUMIFS(Counties!$AE$2:$AE$1583,Counties!$A$2:$A$1583,$A15))/I15,"") | Q15: =IF(K15>0,(SUMIFS(Counties!$AL$2:$AL$1583,Counties!$A$2:$A$1583,$A15)-SUMIFS(Counties!$AM$2:$AM$1583,Counties!$A$2:$A$1583,$A15))/(SUMIFS(Counties!$AL$2:$AL$1583,Counties!$A$2:$A$1583,$A15)+SUMIFS(Counties!$AM$2:$AM$1583,Counties!$A$2:$A$1583,$A15)),"") | R15: =IF(Q15="","",IF(Q15>=0,C15,D15)&" +"&TEXT(ABS(Q15)*100,"0.0")) | S15: =IF(Q15="","",IF(Q15>=0.05,"Great for "&TRIM(RIGHT(SUBSTITUTE(C15," ",REPT(" ",50)),50)),IF(Q15>=0.01,TRIM(RIGHT(SUBSTITUTE(C15," ",REPT(" ",50)),50))&" on track",IF(Q15>-0.01,"Toss-up",IF(Q15>-0.05,TRIM(RIGHT(SUBSTITUTE(D15," ",REPT(" ",50)),50))&" on track","Great for "&TRIM(RIGHT(SUBSTITUTE(D15," ",REPT(" ",50)),50))))))) | T15: =IF(K15=0,"none",IF(OR(M15<0.1,K15<5),"low",IF(M15<0.4,"medium","high"))) | U15: =IFERROR(INDEX('Early Vote'!$C$6:$C$22,MATCH($A15,'Early Vote'!$A$6:$A$22,0)),"") | V15: =IFERROR(INDEX('Early Vote'!$E$6:$E$22,MATCH($A15,'Early Vote'!$A$6:$A$22,0)),"") | W15: =IF(K15>0,SUMIFS(Counties!$AF$2:$AF$1583,Counties!$A$2:$A$1583,$A15,Counties!$AG$2:$AG$1583,1)/SUMIFS(Counties!$AQ$2:$AQ$1583,Counties!$A$2:$A$1583,$A15,Counties!$AG$2:$AG$1583,1),"") | X15: =IF(K15>=3,W15,G15) | Y15: =SUMIFS(Counties!$AK$2:$AK$1583,Counties!$A$2:$A$1583,$A15)/SUMIFS(Counties!$AQ$2:$AQ$1583,Counties!$A$2:$A$1583,$A15) | Z15: =IFERROR(100*SUMIFS(Counties!$AF$2:$AF$1583,Counties!$A$2:$A$1583,$A15,Counties!$AG$2:$AG$1583,1,Counties!$T$2:$T$1583,">=0.1")/SUMIFS(Counties!$AT$2:$AT$1583,Counties!$A$2:$A$1583,$A15,Counties!$AG$2:$AG$1583,1,Counties!$T$2:$T$1583,">=0.1"),"") | AA15: =IFERROR(100*SUMIFS(Counties!$AF$2:$AF$1583,Counties!$A$2:$A$1583,$A15,Counties!$AG$2:$AG$1583,1,Counties!$T$2:$T$1583,"<=-0.1")/SUMIFS(Counties!$AT$2:$AT$1583,Counties!$A$2:$A$1583,$A15,Counties!$AG$2:$AG$1583,1,Counties!$T$2:$T$1583,"<=-0.1"),"") | AB15: No votes counted yet. 2024: R+20.8; with 2022's turnout pattern R+21.3, so Osborn needs a 21.3-pt swing toward D from 2024 to win.
A16: NH | B16: New Hampshire Senate | C16: Chris Pappas | D16: John E. Sununu | E16: =(SUMIFS(Counties!$F$2:$F$1583,Counties!$A$2:$A$1583,$A16)-SUMIFS(Counties!$G$2:$G$1583,Counties!$A$2:$A$1583,$A16))/(SUMIFS(Counties!$F$2:$F$1583,Counties!$A$2:$A$1583,$A16)+SUMIFS(Counties!$G$2:$G$1583,Counties!$A$2:$A$1583,$A16)) | F16: =-SUMIFS(Counties!$AR$2:$AR$1583,Counties!$A$2:$A$1583,$A16)/SUMIFS(Counties!$AQ$2:$AQ$1583,Counties!$A$2:$A$1583,$A16) | G16: 1 | H16: =SUMIFS(Counties!$U$2:$U$1583,Counties!$A$2:$A$1583,$A16) | I16: =SUMIFS(Counties!$AF$2:$AF$1583,Counties!$A$2:$A$1583,$A16) | J16: =IF(H16>0,I16/H16,0) | K16: =COUNTIFS(Counties!$A$2:$A$1583,$A16,Counties!$AG$2:$AG$1583,1) | L16: =COUNTIF(Counties!$A$2:$A$1583,$A16) | M16: =IF(H16>0,SUMIFS(Counties!$U$2:$U$1583,Counties!$A$2:$A$1583,$A16,Counties!$AG$2:$AG$1583,1)/H16,0) | N16: =IF(K16>0,SUMIFS(Counties!$AP$2:$AP$1583,Counties!$A$2:$A$1583,$A16)/SUMIFS(Counties!$AF$2:$AF$1583,Counties!$A$2:$A$1583,$A16,Counties!$AG$2:$AG$1583,1),"") | O16: =IF(N16="","",N16-F16) | P16: =IF(I16>0,(SUMIFS(Counties!$AD$2:$AD$1583,Counties!$A$2:$A$1583,$A16)-SUMIFS(Counties!$AE$2:$AE$1583,Counties!$A$2:$A$1583,$A16))/I16,"") | Q16: =IF(K16>0,(SUMIFS(Counties!$AL$2:$AL$1583,Counties!$A$2:$A$1583,$A16)-SUMIFS(Counties!$AM$2:$AM$1583,Counties!$A$2:$A$1583,$A16))/(SUMIFS(Counties!$AL$2:$AL$1583,Counties!$A$2:$A$1583,$A16)+SUMIFS(Counties!$AM$2:$AM$1583,Counties!$A$2:$A$1583,$A16)),"") | R16: =IF(Q16="","",IF(Q16>=0,C16,D16)&" +"&TEXT(ABS(Q16)*100,"0.0")) | S16: =IF(Q16="","",IF(Q16>=0.05,"Great for "&TRIM(RIGHT(SUBSTITUTE(C16," ",REPT(" ",50)),50)),IF(Q16>=0.01,TRIM(RIGHT(SUBSTITUTE(C16," ",REPT(" ",50)),50))&" on track",IF(Q16>-0.01,"Toss-up",IF(Q16>-0.05,TRIM(RIGHT(SUBSTITUTE(D16," ",REPT(" ",50)),50))&" on track","Great for "&TRIM(RIGHT(SUBSTITUTE(D16," ",REPT(" ",50)),50))))))) | T16: =IF(K16=0,"none",IF(OR(M16<0.1,K16<5),"low",IF(M16<0.4,"medium","high"))) | U16: =IFERROR(INDEX('Early Vote'!$C$6:$C$22,MATCH($A16,'Early Vote'!$A$6:$A$22,0)),"") | V16: =IFERROR(INDEX('Early Vote'!$E$6:$E$22,MATCH($A16,'Early Vote'!$A$6:$A$22,0)),"") | W16: =IF(K16>0,SUMIFS(Counties!$AF$2:$AF$1583,Counties!$A$2:$A$1583,$A16,Counties!$AG$2:$AG$1583,1)/SUMIFS(Counties!$AQ$2:$AQ$1583,Counties!$A$2:$A$1583,$A16,Counties!$AG$2:$AG$1583,1),"") | X16: =IF(K16>=3,W16,G16) | Y16: =SUMIFS(Counties!$AK$2:$AK$1583,Counties!$A$2:$A$1583,$A16)/SUMIFS(Counties!$AQ$2:$AQ$1583,Counties!$A$2:$A$1583,$A16) | Z16: =IFERROR(100*SUMIFS(Counties!$AF$2:$AF$1583,Counties!$A$2:$A$1583,$A16,Counties!$AG$2:$AG$1583,1,Counties!$T$2:$T$1583,">=0.1")/SUMIFS(Counties!$AT$2:$AT$1583,Counties!$A$2:$A$1583,$A16,Counties!$AG$2:$AG$1583,1,Counties!$T$2:$T$1583,">=0.1"),"") | AA16: =IFERROR(100*SUMIFS(Counties!$AF$2:$AF$1583,Counties!$A$2:$A$1583,$A16,Counties!$AG$2:$AG$1583,1,Counties!$T$2:$T$1583,"<=-0.1")/SUMIFS(Counties!$AT$2:$AT$1583,Counties!$A$2:$A$1583,$A16,Counties!$AG$2:$AG$1583,1,Counties!$T$2:$T$1583,"<=-0.1"),"") | AB16: No votes counted yet. 2024: D+2.8; with 2022's turnout pattern D+2.8, so Pappas can absorb up to a 2.8-pt swing toward R from 2024 and still win.
A17: OH | B17: Ohio Senate | C17: Sherrod Brown | D17: Jon Husted | E17: =(SUMIFS(Counties!$F$2:$F$1583,Counties!$A$2:$A$1583,$A17)-SUMIFS(Counties!$G$2:$G$1583,Counties!$A$2:$A$1583,$A17))/(SUMIFS(Counties!$F$2:$F$1583,Counties!$A$2:$A$1583,$A17)+SUMIFS(Counties!$G$2:$G$1583,Counties!$A$2:$A$1583,$A17)) | F17: =-SUMIFS(Counties!$AR$2:$AR$1583,Counties!$A$2:$A$1583,$A17)/SUMIFS(Counties!$AQ$2:$AQ$1583,Counties!$A$2:$A$1583,$A17) | G17: 1 | H17: =SUMIFS(Counties!$U$2:$U$1583,Counties!$A$2:$A$1583,$A17) | I17: =SUMIFS(Counties!$AF$2:$AF$1583,Counties!$A$2:$A$1583,$A17) | J17: =IF(H17>0,I17/H17,0) | K17: =COUNTIFS(Counties!$A$2:$A$1583,$A17,Counties!$AG$2:$AG$1583,1) | L17: =COUNTIF(Counties!$A$2:$A$1583,$A17) | M17: =IF(H17>0,SUMIFS(Counties!$U$2:$U$1583,Counties!$A$2:$A$1583,$A17,Counties!$AG$2:$AG$1583,1)/H17,0) | N17: =IF(K17>0,SUMIFS(Counties!$AP$2:$AP$1583,Counties!$A$2:$A$1583,$A17)/SUMIFS(Counties!$AF$2:$AF$1583,Counties!$A$2:$A$1583,$A17,Counties!$AG$2:$AG$1583,1),"") | O17: =IF(N17="","",N17-F17) | P17: =IF(I17>0,(SUMIFS(Counties!$AD$2:$AD$1583,Counties!$A$2:$A$1583,$A17)-SUMIFS(Counties!$AE$2:$AE$1583,Counties!$A$2:$A$1583,$A17))/I17,"") | Q17: =IF(K17>0,(SUMIFS(Counties!$AL$2:$AL$1583,Counties!$A$2:$A$1583,$A17)-SUMIFS(Counties!$AM$2:$AM$1583,Counties!$A$2:$A$1583,$A17))/(SUMIFS(Counties!$AL$2:$AL$1583,Counties!$A$2:$A$1583,$A17)+SUMIFS(Counties!$AM$2:$AM$1583,Counties!$A$2:$A$1583,$A17)),"") | R17: =IF(Q17="","",IF(Q17>=0,C17,D17)&" +"&TEXT(ABS(Q17)*100,"0.0")) | S17: =IF(Q17="","",IF(Q17>=0.05,"Great for "&TRIM(RIGHT(SUBSTITUTE(C17," ",REPT(" ",50)),50)),IF(Q17>=0.01,TRIM(RIGHT(SUBSTITUTE(C17," ",REPT(" ",50)),50))&" on track",IF(Q17>-0.01,"Toss-up",IF(Q17>-0.05,TRIM(RIGHT(SUBSTITUTE(D17," ",REPT(" ",50)),50))&" on track","Great for "&TRIM(RIGHT(SUBSTITUTE(D17," ",REPT(" ",50)),50))))))) | T17: =IF(K17=0,"none",IF(OR(M17<0.1,K17<5),"low",IF(M17<0.4,"medium","high"))) | U17: =IFERROR(INDEX('Early Vote'!$C$6:$C$22,MATCH($A17,'Early Vote'!$A$6:$A$22,0)),"") | V17: =IFERROR(INDEX('Early Vote'!$E$6:$E$22,MATCH($A17,'Early Vote'!$A$6:$A$22,0)),"") | W17: =IF(K17>0,SUMIFS(Counties!$AF$2:$AF$1583,Counties!$A$2:$A$1583,$A17,Counties!$AG$2:$AG$1583,1)/SUMIFS(Counties!$AQ$2:$AQ$1583,Counties!$A$2:$A$1583,$A17,Counties!$AG$2:$AG$1583,1),"") | X17: =IF(K17>=3,W17,G17) | Y17: =SUMIFS(Counties!$AK$2:$AK$1583,Counties!$A$2:$A$1583,$A17)/SUMIFS(Counties!$AQ$2:$AQ$1583,Counties!$A$2:$A$1583,$A17) | Z17: =IFERROR(100*SUMIFS(Counties!$AF$2:$AF$1583,Counties!$A$2:$A$1583,$A17,Counties!$AG$2:$AG$1583,1,Counties!$T$2:$T$1583,">=0.1")/SUMIFS(Counties!$AT$2:$AT$1583,Counties!$A$2:$A$1583,$A17,Counties!$AG$2:$AG$1583,1,Counties!$T$2:$T$1583,">=0.1"),"") | AA17: =IFERROR(100*SUMIFS(Counties!$AF$2:$AF$1583,Counties!$A$2:$A$1583,$A17,Counties!$AG$2:$AG$1583,1,Counties!$T$2:$T$1583,"<=-0.1")/SUMIFS(Counties!$AT$2:$AT$1583,Counties!$A$2:$A$1583,$A17,Counties!$AG$2:$AG$1583,1,Counties!$T$2:$T$1583,"<=-0.1"),"") | AB17: No votes counted yet. 2024: R+11.3; with 2022's turnout pattern R+11.2, so Brown needs a 11.2-pt swing toward D from 2024 to win.
... A22: KY | B22: Kentucky Senate (bellwether) | C22: Charles Booker | D22: Andy Barr | E22: =(SUMIFS(Counties!$F$2:$F$1583,Counties!$A$2:$A$1583,$A22)-SUMIFS(Counties!$G$2:$G$1583,Counties!$A$2:$A$1583,$A22))/(SUMIFS(Counties!$F$2:$F$1583,Counties!$A$2:$A$1583,$A22)+SUMIFS(Counties!$G$2:$G$1583,Counties!$A$2:$A$1583,$A22)) | F22: =-SUMIFS(Counties!$AR$2:$AR$1583,Counties!$A$2:$A$1583,$A22)/SUMIFS(Counties!$AQ$2:$AQ$1583,Counties!$A$2:$A$1583,$A22) | G22: 1 | H22: =SUMIFS(Counties!$U$2:$U$1583,Counties!$A$2:$A$1583,$A22) | I22: =SUMIFS(Counties!$AF$2:$AF$1583,Counties!$A$2:$A$1583,$A22) | J22: =IF(H22>0,I22/H22,0) | K22: =COUNTIFS(Counties!$A$2:$A$1583,$A22,Counties!$AG$2:$AG$1583,1) | L22: =COUNTIF(Counties!$A$2:$A$1583,$A22) | M22: =IF(H22>0,SUMIFS(Counties!$U$2:$U$1583,Counties!$A$2:$A$1583,$A22,Counties!$AG$2:$AG$1583,1)/H22,0) | N22: =IF(K22>0,SUMIFS(Counties!$AP$2:$AP$1583,Counties!$A$2:$A$1583,$A22)/SUMIFS(Counties!$AF$2:$AF$1583,Counties!$A$2:$A$1583,$A22,Counties!$AG$2:$AG$1583,1),"") | O22: =IF(N22="","",N22-F22) | P22: =IF(I22>0,(SUMIFS(Counties!$AD$2:$AD$1583,Counties!$A$2:$A$1583,$A22)-SUMIFS(Counties!$AE$2:$AE$1583,Counties!$A$2:$A$1583,$A22))/I22,"") | Q22: =IF(K22>0,(SUMIFS(Counties!$AL$2:$AL$1583,Counties!$A$2:$A$1583,$A22)-SUMIFS(Counties!$AM$2:$AM$1583,Counties!$A$2:$A$1583,$A22))/(SUMIFS(Counties!$AL$2:$AL$1583,Counties!$A$2:$A$1583,$A22)+SUMIFS(Counties!$AM$2:$AM$1583,Counties!$A$2:$A$1583,$A22)),"") | R22: =IF(Q22="","",IF(Q22>=0,C22,D22)&" +"&TEXT(ABS(Q22)*100,"0.0")) | S22: =IF(Q22="","",IF(Q22>=0.05,"Great for "&TRIM(RIGHT(SUBSTITUTE(C22," ",REPT(" ",50)),50)),IF(Q22>=0.01,TRIM(RIGHT(SUBSTITUTE(C22," ",REPT(" ",50)),50))&" on track",IF(Q22>-0.01,"Toss-up",IF(Q22>-0.05,TRIM(RIGHT(SUBSTITUTE(D22," ",REPT(" ",50)),50))&" on track","Great for "&TRIM(RIGHT(SUBSTITUTE(D22," ",REPT(" ",50)),50))))))) | T22: =IF(K22=0,"none",IF(OR(M22<0.1,K22<5),"low",IF(M22<0.4,"medium","high"))) | U22: =IFERROR(INDEX('Early Vote'!$C$6:$C$22,MATCH($A22,'Early Vote'!$A$6:$A$22,0)),"") | V22: =IFERROR(INDEX('Early Vote'!$E$6:$E$22,MATCH($A22,'Early Vote'!$A$6:$A$22,0)),"") | W22: =IF(K22>0,SUMIFS(Counties!$AF$2:$AF$1583,Counties!$A$2:$A$1583,$A22,Counties!$AG$2:$AG$1583,1)/SUMIFS(Counties!$AQ$2:$AQ$1583,Counties!$A$2:$A$1583,$A22,Counties!$AG$2:$AG$1583,1),"") | X22: =IF(K22>=3,W22,G22) | Y22: =SUMIFS(Counties!$AK$2:$AK$1583,Counties!$A$2:$A$1583,$A22)/SUMIFS(Counties!$AQ$2:$AQ$1583,Counties!$A$2:$A$1583,$A22) | Z22: =IFERROR(100*SUMIFS(Counties!$AF$2:$AF$1583,Counties!$A$2:$A$1583,$A22,Counties!$AG$2:$AG$1583,1,Counties!$T$2:$T$1583,">=0.1")/SUMIFS(Counties!$AT$2:$AT$1583,Counties!$A$2:$A$1583,$A22,Counties!$AG$2:$AG$1583,1,Counties!$T$2:$T$1583,">=0.1"),"") | AA22: =IFERROR(100*SUMIFS(Counties!$AF$2:$AF$1583,Counties!$A$2:$A$1583,$A22,Counties!$AG$2:$AG$1583,1,Counties!$T$2:$T$1583,"<=-0.1")/SUMIFS(Counties!$AT$2:$AT$1583,Counties!$A$2:$A$1583,$A22,Counties!$AG$2:$AG$1583,1,Counties!$T$2:$T$1583,"<=-0.1"),"") | AB22: No votes counted yet. 2024: R+31.0; with 2022's turnout pattern R+29.8, so Booker needs a 29.8-pt swing toward D from 2024 to win.
A24: How to read it
A25: • Before anything is fully counted there's no projection. The raw margin will mislead early on because states count one vote method first (see each state's read).
A26: • Confidence: low under 10% of the expected vote in complete counties or fewer than 5 counties; medium under 40%; high above.
A27: • Nebraska: the Democratic side is Dan Osborn (independent). His benchmarks use Harris's 2024 margins, which understate him in rural counties (he ran 14 points ahead of Harris statewide in 2024).
A28: • Alaska reports by state House district, not county, and most results come in after 1 AM ET.
A29: • Mississippi's 2022 column is the US House races (no statewide race that year), so its 2022 margins are rough.

Sheet Key Counties
A1: Key counties: why they matter and how they're doing, on margin and turnout
A2: Break-even = the margin the Democratic side needs in that county for a statewide tie if every county swings equally from 2024 and turnout follows 2022's pattern. Turnout index = the county's votes vs its par (2022 pattern x the state's pace): 100 = in line with the state. Weak turnout in a Democratic county raises the margin it needs; strong turnout in a Republican county means Democrats must hold it closer. 'Margin + turnout' combines both in margin points; turnout columns fill in once a county is fully counted. The last row in each state is all its small-town and rural counties together.
A4: State | B4: County | C4: Why it matters | D4: What to watch | E4: Type | F4: Margin 2024 | G4: Swing 20→24 | H4: Margin 2022 | I4: Share of state vote 2024 | J4: Expected share (2022 turnout) | K4: D break-even | L4: Live margin | M4: Est. % in | N4: Live vs break-even | O4: Margin status | P4: Turnout index (100 = state pace) | Q4: Break-even at actual turnout | R4: Turnout index needed at live margin | S4: Turnout effect (pts) | T4: Margin + turnout vs tie pace (pts) | U4: Net votes vs tie pace | V4: Overall read | W4: FIPS
A5: Georgia · 2024: R+2.2 (R+1.1 with 2022's turnout pattern) · Jon Ossoff vs Mike Collins
A6: GA | B6: Fulton | C6: Largest vote bank for Democrats (Atlanta). | D6: Raw D vote margin matters more than the percentage. If turnout lags 2022, Democrats need bigger margins elsewhere. | E6: Big metro core | F6: =Counties!O101 | G6: =Counties!Q101 | H6: =Counties!R101 | I6: =Counties!S101 | J6: =Counties!AQ101/SUMIFS(Counties!$AQ:$AQ,Counties!$A:$A,"GA") | K6: =Counties!T101 | L6: =Counties!AH101 | M6: =Counties!AO101 | N6: =Counties!AN101 | O6: =IF(L6="","not in yet",IF(N6>=0.05,"Great for Ossoff",IF(N6>=0.01,"Ossoff on track",IF(N6>-0.01,"Toss-up",IF(N6>-0.05,"Collins on track","Great for Collins"))))&IF(Counties!AG101=1,""," (partial)")) | P6: =Counties!AU101 | Q6: =Counties!AV101 | R6: =Counties!AW101 | S6: =Counties!AX101 | T6: =Counties!AY101 | U6: =IF(T6="","",T6*Counties!AF101) | V6: =IF(T6="",IF(L6="","not in yet","waiting for the full count"),IF(T6>=0.05,"Great for Ossoff",IF(T6>=0.01,"Ossoff on track",IF(T6>-0.01,"Toss-up",IF(T6>-0.05,"Collins on track","Great for Collins"))))) | W6: 13121
A7: GA | B7: Gwinnett | C7: Most diverse big county in the state; swung slightly R from 2020 to 2024 as Hispanic and Asian voters moved. | D7: Whether the 2024 drift toward R continues or snaps back. Best single read on nonwhite swing voters. | E7: Big metro core | F7: =Counties!O108 | G7: =Counties!Q108 | H7: =Counties!R108 | I7: =Counties!S108 | J7: =Counties!AQ108/SUMIFS(Counties!$AQ:$AQ,Counties!$A:$A,"GA") | K7: =Counties!T108 | L7: =Counties!AH108 | M7: =Counties!AO108 | N7: =Counties!AN108 | O7: =IF(L7="","not in yet",IF(N7>=0.05,"Great for Ossoff",IF(N7>=0.01,"Ossoff on track",IF(N7>-0.01,"Toss-up",IF(N7>-0.05,"Collins on track","Great for Collins"))))&IF(Counties!AG108=1,""," (partial)")) | P7: =Counties!AU108 | Q7: =Counties!AV108 | R7: =Counties!AW108 | S7: =Counties!AX108 | T7: =Counties!AY108 | U7: =IF(T7="","",T7*Counties!AF108) | V7: =IF(T7="",IF(L7="","not in yet","waiting for the full count"),IF(T7>=0.05,"Great for Ossoff",IF(T7>=0.01,"Ossoff on track",IF(T7>-0.01,"Toss-up",IF(T7>-0.05,"Collins on track","Great for Collins"))))) | W7: 13135
A8: GA | B8: Cobb | C8: College-educated suburbs that flipped D in 2016 and kept moving left. | D8: A margin above 2024 means the suburban realignment is still paying Democrats. | E8: Big metro core | F8: =Counties!O74 | G8: =Counties!Q74 | H8: =Counties!R74 | I8: =Counties!S74 | J8: =Counties!AQ74/SUMIFS(Counties!$AQ:$AQ,Counties!$A:$A,"GA") | K8: =Counties!T74 | L8: =Counties!AH74 | M8: =Counties!AO74 | N8: =Counties!AN74 | O8: =IF(L8="","not in yet",IF(N8>=0.05,"Great for Ossoff",IF(N8>=0.01,"Ossoff on track",IF(N8>-0.01,"Toss-up",IF(N8>-0.05,"Collins on track","Great for Collins"))))&IF(Counties!AG74=1,""," (partial)")) | P8: =Counties!AU74 | Q8: =Counties!AV74 | R8: =Counties!AW74 | S8: =Counties!AX74 | T8: =Counties!AY74 | U8: =IF(T8="","",T8*Counties!AF74) | V8: =IF(T8="",IF(L8="","not in yet","waiting for the full count"),IF(T8>=0.05,"Great for Ossoff",IF(T8>=0.01,"Ossoff on track",IF(T8>-0.01,"Toss-up",IF(T8>-0.05,"Collins on track","Great for Collins"))))) | W8: 13067
A9: GA | B9: DeKalb | C9: Heavily Black, highly educated D base. | D9: Turnout versus 2022. Its margin barely moves, so the vote count is the signal. | E9: Big metro core | F9: =Counties!O84 | G9: =Counties!Q84 | H9: =Counties!R84 | I9: =Counties!S84 | J9: =Counties!AQ84/SUMIFS(Counties!$AQ:$AQ,Counties!$A:$A,"GA") | K9: =Counties!T84 | L9: =Counties!AH84 | M9: =Counties!AO84 | N9: =Counties!AN84 | O9: =IF(L9="","not in yet",IF(N9>=0.05,"Great for Ossoff",IF(N9>=0.01,"Ossoff on track",IF(N9>-0.01,"Toss-up",IF(N9>-0.05,"Collins on track","Great for Collins"))))&IF(Counties!AG84=1,""," (partial)")) | P9: =Counties!AU84 | Q9: =Counties!AV84 | R9: =Counties!AW84 | S9: =Counties!AX84 | T9: =Counties!AY84 | U9: =IF(T9="","",T9*Counties!AF84) | V9: =IF(T9="",IF(L9="","not in yet","waiting for the full count"),IF(T9>=0.05,"Great for Ossoff",IF(T9>=0.01,"Ossoff on track",IF(T9>-0.01,"Toss-up",IF(T9>-0.05,"Collins on track","Great for Collins"))))) | W9: 13089
A10: GA | B10: Cherokee | C10: Georgia's biggest Republican vote bank: a fast-growing exurb north of Atlanta that gave Trump about 63,000 net votes in 2024. | D10: Republican turnout. Its margin barely moves (R+40 in 2020, 2022 and 2024), so a turnout index under 100 here is the clearest sign of a Republican enthusiasm gap. | E10: Mid-size/working metro | F10: =Counties!O69 | G10: =Counties!Q69 | H10: =Counties!R69 | I10: =Counties!S69 | J10: =Counties!AQ69/SUMIFS(Counties!$AQ:$AQ,Counties!$A:$A,"GA") | K10: =Counties!T69 | L10: =Counties!AH69 | M10: =Counties!AO69 | N10: =Counties!AN69 | O10: =IF(L10="","not in yet",IF(N10>=0.05,"Great for Ossoff",IF(N10>=0.01,"Ossoff on track",IF(N10>-0.01,"Toss-up",IF(N10>-0.05,"Collins on track","Great for Collins"))))&IF(Counties!AG69=1,""," (partial)")) | P10: =Counties!AU69 | Q10: =Counties!AV69 | R10: =Counties!AW69 | S10: =Counties!AX69 | T10: =Counties!AY69 | U10: =IF(T10="","",T10*Counties!AF69) | V10: =IF(T10="",IF(L10="","not in yet","waiting for the full count"),IF(T10>=0.05,"Great for Ossoff",IF(T10>=0.01,"Ossoff on track",IF(T10>-0.01,"Toss-up",IF(T10>-0.05,"Collins on track","Great for Collins"))))) | W10: 13057
A11: GA | B11: Chatham | C11: Savannah. A mid-size D county with a large Black population. | D11: A non-Atlanta check on Black turnout and margin. | E11: Mid-size/working metro | F11: =Counties!O66 | G11: =Counties!Q66 | H11: =Counties!R66 | I11: =Counties!S66 | J11: =Counties!AQ66/SUMIFS(Counties!$AQ:$AQ,Counties!$A:$A,"GA") | K11: =Counties!T66 | L11: =Counties!AH66 | M11: =Counties!AO66 | N11: =Counties!AN66 | O11: =IF(L11="","not in yet",IF(N11>=0.05,"Great for Ossoff",IF(N11>=0.01,"Ossoff on track",IF(N11>-0.01,"Toss-up",IF(N11>-0.05,"Collins on track","Great for Collins"))))&IF(Counties!AG66=1,""," (partial)")) | P11: =Counties!AU66 | Q11: =Counties!AV66 | R11: =Counties!AW66 | S11: =Counties!AX66 | T11: =Counties!AY66 | U11: =IF(T11="","",T11*Counties!AF66) | V11: =IF(T11="",IF(L11="","not in yet","waiting for the full count"),IF(T11>=0.05,"Great for Ossoff",IF(T11>=0.01,"Ossoff on track",IF(T11>-0.01,"Toss-up",IF(T11>-0.05,"Collins on track","Great for Collins"))))) | W11: 13051
A12: GA | B12: Forsyth | C12: Wealthy, college-educated exurb that's still strongly R. | D12: Any shrinking of the R margin here signals college-educated Republicans defecting. | E12: College suburb/metro | F12: =Counties!O99 | G12: =Counties!Q99 | H12: =Counties!R99 | I12: =Counties!S99 | J12: =Counties!AQ99/SUMIFS(Counties!$AQ:$AQ,Counties!$A:$A,"GA") | K12: =Counties!T99 | L12: =Counties!AH99 | M12: =Counties!AO99 | N12: =Counties!AN99 | O12: =IF(L12="","not in yet",IF(N12>=0.05,"Great for Ossoff",IF(N12>=0.01,"Ossoff on track",IF(N12>-0.01,"Toss-up",IF(N12>-0.05,"Collins on track","Great for Collins"))))&IF(Counties!AG99=1,""," (partial)")) | P12: =Counties!AU99 | Q12: =Counties!AV99 | R12: =Counties!AW99 | S12: =Counties!AX99 | T12: =Counties!AY99 | U12: =IF(T12="","",T12*Counties!AF99) | V12: =IF(T12="",IF(L12="","not in yet","waiting for the full count"),IF(T12>=0.05,"Great for Ossoff",IF(T12>=0.01,"Ossoff on track",IF(T12>-0.01,"Toss-up",IF(T12>-0.05,"Collins on track","Great for Collins"))))) | W12: 13117
A13: GA | B13: Henry | C13: Fast-growing Black suburb south of Atlanta, and the biggest D gain of any large Georgia county from 2020 to 2024 (about 9 points). | D13: Whether that gain holds in a midterm with lower Black turnout. | E13: Black Belt | F13: =Counties!O116 | G13: =Counties!Q116 | H13: =Counties!R116 | I13: =Counties!S116 | J13: =Counties!AQ116/SUMIFS(Counties!$AQ:$AQ,Counties!$A:$A,"GA") | K13: =Counties!T116 | L13: =Counties!AH116 | M13: =Counties!AO116 | N13: =Counties!AN116 | O13: =IF(L13="","not in yet",IF(N13>=0.05,"Great for Ossoff",IF(N13>=0.01,"Ossoff on track",IF(N13>-0.01,"Toss-up",IF(N13>-0.05,"Collins on track","Great for Collins"))))&IF(Counties!AG116=1,""," (partial)")) | P13: =Counties!AU116 | Q13: =Counties!AV116 | R13: =Counties!AW116 | S13: =Counties!AX116 | T13: =Counties!AY116 | U13: =IF(T13="","",T13*Counties!AF116) | V13: =IF(T13="",IF(L13="","not in yet","waiting for the full count"),IF(T13>=0.05,"Great for Ossoff",IF(T13>=0.01,"Ossoff on track",IF(T13>-0.01,"Toss-up",IF(T13>-0.05,"Collins on track","Great for Collins"))))) | W13: 13151
A14: GA | B14: Clayton | C14: Most Democratic county in Georgia, majority Black. | D14: Turnout. Its margin barely moves, so the raw vote count is what matters. | E14: Black Belt | F14: =Counties!O72 | G14: =Counties!Q72 | H14: =Counties!R72 | I14: =Counties!S72 | J14: =Counties!AQ72/SUMIFS(Counties!$AQ:$AQ,Counties!$A:$A,"GA") | K14: =Counties!T72 | L14: =Counties!AH72 | M14: =Counties!AO72 | N14: =Counties!AN72 | O14: =IF(L14="","not in yet",IF(N14>=0.05,"Great for Ossoff",IF(N14>=0.01,"Ossoff on track",IF(N14>-0.01,"Toss-up",IF(N14>-0.05,"Collins on track","Great for Collins"))))&IF(Counties!AG72=1,""," (partial)")) | P14: =Counties!AU72 | Q14: =Counties!AV72 | R14: =Counties!AW72 | S14: =Counties!AX72 | T14: =Counties!AY72 | U14: =IF(T14="","",T14*Counties!AF72) | V14: =IF(T14="",IF(L14="","not in yet","waiting for the full count"),IF(T14>=0.05,"Great for Ossoff",IF(T14>=0.01,"Ossoff on track",IF(T14>-0.01,"Toss-up",IF(T14>-0.05,"Collins on track","Great for Collins"))))) | W14: 13063
A15: GA | B15: Hall | C15: Gainesville. The third-biggest R net-vote county, and nearly 30% Hispanic. | D15: Margin and turnout both. An R margin well under R+44 points to Hispanic voters moving back toward Democrats; turnout under the state pace means the exurban base isn't showing up. | E15: Mid-size/working metro | F15: =Counties!O110 | G15: =Counties!Q110 | H15: =Counties!R110 | I15: =Counties!S110 | J15: =Counties!AQ110/SUMIFS(Counties!$AQ:$AQ,Counties!$A:$A,"GA") | K15: =Counties!T110 | L15: =Counties!AH110 | M15: =Counties!AO110 | N15: =Counties!AN110 | O15: =IF(L15="","not in yet",IF(N15>=0.05,"Great for Ossoff",IF(N15>=0.01,"Ossoff on track",IF(N15>-0.01,"Toss-up",IF(N15>-0.05,"Collins on track","Great for Collins"))))&IF(Counties!AG110=1,""," (partial)")) | P15: =Counties!AU110 | Q15: =Counties!AV110 | R15: =Counties!AW110 | S15: =Counties!AX110 | T15: =Counties!AY110 | U15: =IF(T15="","",T15*Counties!AF110) | V15: =IF(T15="",IF(L15="","not in yet","waiting for the full count"),IF(T15>=0.05,"Great for Ossoff",IF(T15>=0.01,"Ossoff on track",IF(T15>-0.01,"Toss-up",IF(T15>-0.05,"Collins on track","Great for Collins"))))) | W15: 13139
A16: GA | B16: Bartow | C16: Northwest Georgia exurb along I-75 at R+51, a stand-in for the small-town Republican base. | D16: Turnout. The margin is locked in (R+51 in 2020, 2022 and 2024), so the vote count is the signal. | E16: Mid-size/working metro | F16: =Counties!O49 | G16: =Counties!Q49 | H16: =Counties!R49 | I16: =Counties!S49 | J16: =Counties!AQ49/SUMIFS(Counties!$AQ:$AQ,Counties!$A:$A,"GA") | K16: =Counties!T49 | L16: =Counties!AH49 | M16: =Counties!AO49 | N16: =Counties!AN49 | O16: =IF(L16="","not in yet",IF(N16>=0.05,"Great for Ossoff",IF(N16>=0.01,"Ossoff on track",IF(N16>-0.01,"Toss-up",IF(N16>-0.05,"Collins on track","Great for Collins"))))&IF(Counties!AG49=1,""," (partial)")) | P16: =Counties!AU49 | Q16: =Counties!AV49 | R16: =Counties!AW49 | S16: =Counties!AX49 | T16: =Counties!AY49 | U16: =IF(T16="","",T16*Counties!AF49) | V16: =IF(T16="",IF(L16="","not in yet","waiting for the full count"),IF(T16>=0.05,"Great for Ossoff",IF(T16>=0.01,"Ossoff on track",IF(T16>-0.01,"Toss-up",IF(T16>-0.05,"Collins on track","Great for Collins"))))) | W16: 13015
A17: GA | B17: All rural (103) | C17: Every small-town and rural county together: the Republican base's turnout test. | D17: Turnout index from its finished counties. Above 100 means the rural base is a bigger share of the vote than a tie assumes; the margin rarely moves much. | E17: Small town & rural | F17: =Types!M9 | J17: =Types!L9 | K17: =Types!P9 | L17: =Types!S9 | M17: =IFERROR(Types!E9/Types!D9,"") | N17: =IF(L17="","",L17-K17) | O17: =IF(Types!F9=0,"not in yet",IF(N17>=0.05,"Great for Ossoff",IF(N17>=0.01,"Ossoff on track",IF(N17>-0.01,"Toss-up",IF(N17>-0.05,"Collins on track","Great for Collins"))))&" (projected)") | P17: =Types!V9 | Q17: =Types!W9 | S17: =IF(Q17="","",K17-Q17) | T17: =Types!X9 | U17: =Types!Y9 | V17: =IF(T17="","not in yet",IF(T17>=0.05,"Great for Ossoff",IF(T17>=0.01,"Ossoff on track",IF(T17>-0.01,"Toss-up",IF(T17>-0.05,"Collins on track","Great for Collins"))))&" (finished counties)")
A18: Iowa · 2024: R+13.4 (R+13.2 with 2022's turnout pattern) · Josh Turek vs Ashley Hinson
A19: IA | B19: Polk | C19: Des Moines. The D vote bank, about 15% of the state's vote. | D19: Margin and turnout. Democrats need it well above 2024's +11. | E19: Mid-size/working metro | F19: =Counties!O277 | G19: =Counties!Q277 | H19: =Counties!R277 | I19: =Counties!S277 | J19: =Counties!AQ277/SUMIFS(Counties!$AQ:$AQ,Counties!$A:$A,"IA") | K19: =Counties!T277 | L19: =Counties!AH277 | M19: =Counties!AO277 | N19: =Counties!AN277 | O19: =IF(L19="","not in yet",IF(N19>=0.05,"Great for Turek",IF(N19>=0.01,"Turek on track",IF(N19>-0.01,"Toss-up",IF(N19>-0.05,"Hinson on track","Great for Hinson"))))&IF(Counties!AG277=1,""," (partial)")) | P19: =Counties!AU277 | Q19: =Counties!AV277 | R19: =Counties!AW277 | S19: =Counties!AX277 | T19: =Counties!AY277 | U19: =IF(T19="","",T19*Counties!AF277) | V19: =IF(T19="",IF(L19="","not in yet","waiting for the full count"),IF(T19>=0.05,"Great for Turek",IF(T19>=0.01,"Turek on track",IF(T19>-0.01,"Toss-up",IF(T19>-0.05,"Hinson on track","Great for Hinson"))))) | W19: 19153
